{"timestamp": "2025-07-21T22:30:01.416276", "level": "INFO", "logger": "root", "message": "Logging system initialized", "module": "logging_config", "function": "setup_logging", "line": 185}
{"timestamp": "2025-07-21T22:30:01.416420", "level": "INFO", "logger": "root", "message": "Log level: INFO", "module": "logging_config", "function": "setup_logging", "line": 186}
{"timestamp": "2025-07-21T22:30:01.416515", "level": "INFO", "logger": "root", "message": "Log directory: C:\\Users\\Robert Casanova\\OneDrive\\Documents\\economics-ai-dashboard-v2\\logs\\cleanup", "module": "logging_config", "function": "setup_logging", "line": 187}
{"timestamp": "2025-07-21T22:33:13.327659", "level": "INFO", "logger": "root", "message": "Logging system initialized", "module": "logging_config", "function": "setup_logging", "line": 185}
{"timestamp": "2025-07-21T22:33:13.336833", "level": "INFO", "logger": "root", "message": "Log level: INFO", "module": "logging_config", "function": "setup_logging", "line": 186}
{"timestamp": "2025-07-21T22:33:13.336973", "level": "INFO", "logger": "root", "message": "Log directory: C:\\Users\\Robert Casanova\\OneDrive\\Documents\\economics-ai-dashboard-v2\\logs\\cleanup", "module": "logging_config", "function": "setup_logging", "line": 187}
{"timestamp": "2025-07-21T22:33:13.337174", "level": "INFO", "logger": "cleanup_workflow", "message": "Starting analysis for Source 3", "module": "run_source_cleanup", "function": "analyze_source", "line": 92}
{"timestamp": "2025-07-21T22:33:13.337932", "level": "ERROR", "logger": "cleanup_workflow", "message": "Error analyzing source 3: Execution failed on sql '\n        SELECT id, name, file_path, extraction_date\n        FROM data_sources\n        WHERE id = ?\n        ': no such table: data_sources", "module": "run_source_cleanup", "function": "analyze_source", "line": 131}
{"timestamp": "2025-07-21T22:33:13.343281", "level": "ERROR", "logger": "cleanup_operations", "message": "Error during cleanup: Execution failed on sql '\n        SELECT id, name, file_path, extraction_date\n        FROM data_sources\n        WHERE id = ?\n        ': no such table: data_sources", "module": "logging_config", "function": "log_error", "line": 89, "source_id": 3, "operation": "cleanup_error", "error_type": "DatabaseError", "exception": "Traceback (most recent call last):\n  File \"C:\\Users\\Robert Casanova\\AppData\\Roaming\\Python\\Python313\\site-packages\\pandas\\io\\sql.py\", line 2664, in execute\n    cur.execute(sql, *args)\n    ~~~~~~~~~~~^^^^^^^^^^^^\nsqlite3.OperationalError: no such table: data_sources\n\nThe above exception was the direct cause of the following exception:\n\nTraceback (most recent call last):\n  File \"C:\\Users\\Robert Casanova\\OneDrive\\Documents\\economics-ai-dashboard-v2\\src\\pipeline\\run_source_cleanup.py\", line 96, in analyze_source\n    source_info = self.get_source_info(source_id)\n  File \"C:\\Users\\Robert Casanova\\OneDrive\\Documents\\economics-ai-dashboard-v2\\src\\pipeline\\run_source_cleanup.py\", line 77, in get_source_info\n    result = pd.read_sql_query(query, conn, params=[source_id])\n  File \"C:\\Users\\Robert Casanova\\AppData\\Roaming\\Python\\Python313\\site-packages\\pandas\\io\\sql.py\", line 528, in read_sql_query\n    return pandas_sql.read_query(\n           ~~~~~~~~~~~~~~~~~~~~~^\n        sql,\n        ^^^^\n    ...<6 lines>...\n        dtype_backend=dtype_backend,\n        ^^^^^^^^^^^^^^^^^^^^^^^^^^^^\n    )\n    ^\n  File \"C:\\Users\\Robert Casanova\\AppData\\Roaming\\Python\\Python313\\site-packages\\pandas\\io\\sql.py\", line 2728, in read_query\n    cursor = self.execute(sql, params)\n  File \"C:\\Users\\Robert Casanova\\AppData\\Roaming\\Python\\Python313\\site-packages\\pandas\\io\\sql.py\", line 2676, in execute\n    raise ex from exc\npandas.errors.DatabaseError: Execution failed on sql '\n        SELECT id, name, file_path, extraction_date\n        FROM data_sources\n        WHERE id = ?\n        ': no such table: data_sources"}
{"timestamp": "2025-07-21T22:33:13.345070", "level": "ERROR", "logger": "cleanup_workflow", "message": "Failed to process source 3: Execution failed on sql '\n        SELECT id, name, file_path, extraction_date\n        FROM data_sources\n        WHERE id = ?\n        ': no such table: data_sources", "module": "run_source_cleanup", "function": "cleanup_multiple_sources", "line": 282}
{"timestamp": "2025-07-21T22:33:13.346407", "level": "ERROR", "logger": "cleanup_operations", "message": "Error during cleanup: Execution failed on sql '\n        SELECT id, name, file_path, extraction_date\n        FROM data_sources\n        WHERE id = ?\n        ': no such table: data_sources", "module": "logging_config", "function": "log_error", "line": 89, "source_id": 3, "operation": "cleanup_error", "error_type": "DatabaseError", "exception": "Traceback (most recent call last):\n  File \"C:\\Users\\Robert Casanova\\AppData\\Roaming\\Python\\Python313\\site-packages\\pandas\\io\\sql.py\", line 2664, in execute\n    cur.execute(sql, *args)\n    ~~~~~~~~~~~^^^^^^^^^^^^\nsqlite3.OperationalError: no such table: data_sources\n\nThe above exception was the direct cause of the following exception:\n\nTraceback (most recent call last):\n  File \"C:\\Users\\Robert Casanova\\OneDrive\\Documents\\economics-ai-dashboard-v2\\src\\pipeline\\run_source_cleanup.py\", line 272, in cleanup_multiple_sources\n    self.analyze_source(source_id, current_file)\n    ~~~~~~~~~~~~~~~~~~~^^^^^^^^^^^^^^^^^^^^^^^^^\n  File \"C:\\Users\\Robert Casanova\\OneDrive\\Documents\\economics-ai-dashboard-v2\\src\\pipeline\\run_source_cleanup.py\", line 96, in analyze_source\n    source_info = self.get_source_info(source_id)\n  File \"C:\\Users\\Robert Casanova\\OneDrive\\Documents\\economics-ai-dashboard-v2\\src\\pipeline\\run_source_cleanup.py\", line 77, in get_source_info\n    result = pd.read_sql_query(query, conn, params=[source_id])\n  File \"C:\\Users\\Robert Casanova\\AppData\\Roaming\\Python\\Python313\\site-packages\\pandas\\io\\sql.py\", line 528, in read_sql_query\n    return pandas_sql.read_query(\n           ~~~~~~~~~~~~~~~~~~~~~^\n        sql,\n        ^^^^\n    ...<6 lines>...\n        dtype_backend=dtype_backend,\n        ^^^^^^^^^^^^^^^^^^^^^^^^^^^^\n    )\n    ^\n  File \"C:\\Users\\Robert Casanova\\AppData\\Roaming\\Python\\Python313\\site-packages\\pandas\\io\\sql.py\", line 2728, in read_query\n    cursor = self.execute(sql, params)\n  File \"C:\\Users\\Robert Casanova\\AppData\\Roaming\\Python\\Python313\\site-packages\\pandas\\io\\sql.py\", line 2676, in execute\n    raise ex from exc\npandas.errors.DatabaseError: Execution failed on sql '\n        SELECT id, name, file_path, extraction_date\n        FROM data_sources\n        WHERE id = ?\n        ': no such table: data_sources"}
{"timestamp": "2025-07-21T22:34:13.712415", "level": "INFO", "logger": "root", "message": "Logging system initialized", "module": "logging_config", "function": "setup_logging", "line": 185}
{"timestamp": "2025-07-21T22:34:13.712566", "level": "INFO", "logger": "root", "message": "Log level: INFO", "module": "logging_config", "function": "setup_logging", "line": 186}
{"timestamp": "2025-07-21T22:34:13.712644", "level": "INFO", "logger": "root", "message": "Log directory: C:\\Users\\Robert Casanova\\OneDrive\\Documents\\economics-ai-dashboard-v2\\logs\\cleanup", "module": "logging_config", "function": "setup_logging", "line": 187}
{"timestamp": "2025-07-21T22:34:13.712715", "level": "INFO", "logger": "cleanup_workflow", "message": "Starting analysis for Source 3", "module": "run_source_cleanup", "function": "analyze_source", "line": 92}
{"timestamp": "2025-07-21T22:34:13.713409", "level": "ERROR", "logger": "cleanup_workflow", "message": "Error analyzing source 3: Execution failed on sql '\n        SELECT id, name, file_path, extraction_date\n        FROM data_sources\n        WHERE id = ?\n        ': no such table: data_sources", "module": "run_source_cleanup", "function": "analyze_source", "line": 131}
{"timestamp": "2025-07-21T22:34:13.715300", "level": "ERROR", "logger": "cleanup_operations", "message": "Error during cleanup: Execution failed on sql '\n        SELECT id, name, file_path, extraction_date\n        FROM data_sources\n        WHERE id = ?\n        ': no such table: data_sources", "module": "logging_config", "function": "log_error", "line": 89, "source_id": 3, "operation": "cleanup_error", "error_type": "DatabaseError", "exception": "Traceback (most recent call last):\n  File \"C:\\Users\\Robert Casanova\\AppData\\Roaming\\Python\\Python313\\site-packages\\pandas\\io\\sql.py\", line 2664, in execute\n    cur.execute(sql, *args)\n    ~~~~~~~~~~~^^^^^^^^^^^^\nsqlite3.OperationalError: no such table: data_sources\n\nThe above exception was the direct cause of the following exception:\n\nTraceback (most recent call last):\n  File \"C:\\Users\\Robert Casanova\\OneDrive\\Documents\\economics-ai-dashboard-v2\\src\\pipeline\\run_source_cleanup.py\", line 96, in analyze_source\n    source_info = self.get_source_info(source_id)\n  File \"C:\\Users\\Robert Casanova\\OneDrive\\Documents\\economics-ai-dashboard-v2\\src\\pipeline\\run_source_cleanup.py\", line 77, in get_source_info\n    result = pd.read_sql_query(query, conn, params=[source_id])\n  File \"C:\\Users\\Robert Casanova\\AppData\\Roaming\\Python\\Python313\\site-packages\\pandas\\io\\sql.py\", line 528, in read_sql_query\n    return pandas_sql.read_query(\n           ~~~~~~~~~~~~~~~~~~~~~^\n        sql,\n        ^^^^\n    ...<6 lines>...\n        dtype_backend=dtype_backend,\n        ^^^^^^^^^^^^^^^^^^^^^^^^^^^^\n    )\n    ^\n  File \"C:\\Users\\Robert Casanova\\AppData\\Roaming\\Python\\Python313\\site-packages\\pandas\\io\\sql.py\", line 2728, in read_query\n    cursor = self.execute(sql, params)\n  File \"C:\\Users\\Robert Casanova\\AppData\\Roaming\\Python\\Python313\\site-packages\\pandas\\io\\sql.py\", line 2676, in execute\n    raise ex from exc\npandas.errors.DatabaseError: Execution failed on sql '\n        SELECT id, name, file_path, extraction_date\n        FROM data_sources\n        WHERE id = ?\n        ': no such table: data_sources"}
{"timestamp": "2025-07-21T22:34:13.727670", "level": "ERROR", "logger": "cleanup_workflow", "message": "Failed to process source 3: Execution failed on sql '\n        SELECT id, name, file_path, extraction_date\n        FROM data_sources\n        WHERE id = ?\n        ': no such table: data_sources", "module": "run_source_cleanup", "function": "cleanup_multiple_sources", "line": 282}
{"timestamp": "2025-07-21T22:34:13.732788", "level": "ERROR", "logger": "cleanup_operations", "message": "Error during cleanup: Execution failed on sql '\n        SELECT id, name, file_path, extraction_date\n        FROM data_sources\n        WHERE id = ?\n        ': no such table: data_sources", "module": "logging_config", "function": "log_error", "line": 89, "source_id": 3, "operation": "cleanup_error", "error_type": "DatabaseError", "exception": "Traceback (most recent call last):\n  File \"C:\\Users\\Robert Casanova\\AppData\\Roaming\\Python\\Python313\\site-packages\\pandas\\io\\sql.py\", line 2664, in execute\n    cur.execute(sql, *args)\n    ~~~~~~~~~~~^^^^^^^^^^^^\nsqlite3.OperationalError: no such table: data_sources\n\nThe above exception was the direct cause of the following exception:\n\nTraceback (most recent call last):\n  File \"C:\\Users\\Robert Casanova\\OneDrive\\Documents\\economics-ai-dashboard-v2\\src\\pipeline\\run_source_cleanup.py\", line 272, in cleanup_multiple_sources\n    self.analyze_source(source_id, current_file)\n    ~~~~~~~~~~~~~~~~~~~^^^^^^^^^^^^^^^^^^^^^^^^^\n  File \"C:\\Users\\Robert Casanova\\OneDrive\\Documents\\economics-ai-dashboard-v2\\src\\pipeline\\run_source_cleanup.py\", line 96, in analyze_source\n    source_info = self.get_source_info(source_id)\n  File \"C:\\Users\\Robert Casanova\\OneDrive\\Documents\\economics-ai-dashboard-v2\\src\\pipeline\\run_source_cleanup.py\", line 77, in get_source_info\n    result = pd.read_sql_query(query, conn, params=[source_id])\n  File \"C:\\Users\\Robert Casanova\\AppData\\Roaming\\Python\\Python313\\site-packages\\pandas\\io\\sql.py\", line 528, in read_sql_query\n    return pandas_sql.read_query(\n           ~~~~~~~~~~~~~~~~~~~~~^\n        sql,\n        ^^^^\n    ...<6 lines>...\n        dtype_backend=dtype_backend,\n        ^^^^^^^^^^^^^^^^^^^^^^^^^^^^\n    )\n    ^\n  File \"C:\\Users\\Robert Casanova\\AppData\\Roaming\\Python\\Python313\\site-packages\\pandas\\io\\sql.py\", line 2728, in read_query\n    cursor = self.execute(sql, params)\n  File \"C:\\Users\\Robert Casanova\\AppData\\Roaming\\Python\\Python313\\site-packages\\pandas\\io\\sql.py\", line 2676, in execute\n    raise ex from exc\npandas.errors.DatabaseError: Execution failed on sql '\n        SELECT id, name, file_path, extraction_date\n        FROM data_sources\n        WHERE id = ?\n        ': no such table: data_sources"}
{"timestamp": "2025-07-21T22:44:28.008492", "level": "INFO", "logger": "root", "message": "Logging system initialized", "module": "logging_config", "function": "setup_logging", "line": 185}
{"timestamp": "2025-07-21T22:44:28.008615", "level": "INFO", "logger": "root", "message": "Log level: INFO", "module": "logging_config", "function": "setup_logging", "line": 186}
{"timestamp": "2025-07-21T22:44:28.008696", "level": "INFO", "logger": "root", "message": "Log directory: C:\\Users\\Robert Casanova\\OneDrive\\Documents\\economics-ai-dashboard-v2\\logs\\cleanup", "module": "logging_config", "function": "setup_logging", "line": 187}
{"timestamp": "2025-07-21T22:44:28.008770", "level": "INFO", "logger": "cleanup_workflow", "message": "Starting analysis for Source 3", "module": "run_source_cleanup", "function": "analyze_source", "line": 74}
{"timestamp": "2025-07-21T22:44:28.064363", "level": "INFO", "logger": "cleanup_workflow", "message": "Analysis complete for Source 3: 12 keep, 51 remove, 5 modify", "module": "run_source_cleanup", "function": "analyze_source", "line": 93}
{"timestamp": "2025-07-21T22:44:28.064475", "level": "INFO", "logger": "cleanup_operations", "message": "Cleanup action: analysis_complete - 68 records", "module": "logging_config", "function": "log_cleanup_action", "line": 66, "source_id": 3, "operation": "cleanup_analysis_complete", "records_affected": 68}
{"timestamp": "2025-07-21T22:44:28.065041", "level": "INFO", "logger": "cleanup_workflow", "message": "Starting cleanup execution for Source 3", "module": "run_source_cleanup", "function": "execute_cleanup", "line": 126}
{"timestamp": "2025-07-21T22:44:28.065184", "level": "ERROR", "logger": "cleanup_workflow", "message": "Failed to process source 3: Database not found at data\\database\\economics_ai.db", "module": "run_source_cleanup", "function": "cleanup_multiple_sources", "line": 260}
{"timestamp": "2025-07-21T22:44:28.066618", "level": "ERROR", "logger": "cleanup_operations", "message": "Error during cleanup: Database not found at data\\database\\economics_ai.db", "module": "logging_config", "function": "log_error", "line": 89, "source_id": 3, "operation": "cleanup_error", "error_type": "FileNotFoundError", "exception": "Traceback (most recent call last):\n  File \"C:\\Users\\Robert Casanova\\OneDrive\\Documents\\economics-ai-dashboard-v2\\src\\pipeline\\run_source_cleanup.py\", line 253, in cleanup_multiple_sources\n    new_file = self.execute_cleanup(source_id, current_file, auto_confirm)\n  File \"C:\\Users\\Robert Casanova\\OneDrive\\Documents\\economics-ai-dashboard-v2\\src\\pipeline\\run_source_cleanup.py\", line 129, in execute_cleanup\n    backup_path = self.backup_manager.create_backup(\n        tag=\"_cleanup\",\n        source_id=source_id\n    )\n  File \"C:\\Users\\Robert Casanova\\OneDrive\\Documents\\economics-ai-dashboard-v2\\src\\utils\\backup_manager.py\", line 68, in create_backup\n    raise FileNotFoundError(f\"Database not found at {self.db_path}\")\nFileNotFoundError: Database not found at data\\database\\economics_ai.db"}
{"timestamp": "2025-07-21T22:46:52.307489", "level": "INFO", "logger": "root", "message": "Logging system initialized", "module": "logging_config", "function": "setup_logging", "line": 185}
{"timestamp": "2025-07-21T22:46:52.307594", "level": "INFO", "logger": "root", "message": "Log level: INFO", "module": "logging_config", "function": "setup_logging", "line": 186}
{"timestamp": "2025-07-21T22:46:52.307692", "level": "INFO", "logger": "root", "message": "Log directory: C:\\Users\\Robert Casanova\\OneDrive\\Documents\\economics-ai-dashboard-v2\\logs\\cleanup", "module": "logging_config", "function": "setup_logging", "line": 187}
{"timestamp": "2025-07-21T22:46:52.307756", "level": "INFO", "logger": "cleanup_workflow", "message": "Starting analysis for Source 3", "module": "run_source_cleanup", "function": "analyze_source", "line": 74}
{"timestamp": "2025-07-21T22:46:52.351430", "level": "INFO", "logger": "cleanup_workflow", "message": "Analysis complete for Source 3: 12 keep, 51 remove, 5 modify", "module": "run_source_cleanup", "function": "analyze_source", "line": 93}
{"timestamp": "2025-07-21T22:46:52.351509", "level": "INFO", "logger": "cleanup_operations", "message": "Cleanup action: analysis_complete - 68 records", "module": "logging_config", "function": "log_cleanup_action", "line": 66, "source_id": 3, "operation": "cleanup_analysis_complete", "records_affected": 68}
{"timestamp": "2025-07-21T22:46:52.352027", "level": "INFO", "logger": "cleanup_workflow", "message": "Starting cleanup execution for Source 3", "module": "run_source_cleanup", "function": "execute_cleanup", "line": 126}
{"timestamp": "2025-07-21T22:46:52.353530", "level": "INFO", "logger": "src.utils.backup_manager", "message": "Backup created: backups\\economics_ai__cleanup_source3_20250721_184652.db", "module": "backup_manager", "function": "create_backup", "line": 109}
{"timestamp": "2025-07-21T22:46:52.353589", "level": "INFO", "logger": "src.utils.backup_manager", "message": "Checksum: d41d8cd98f00b204e9800998ecf8427e", "module": "backup_manager", "function": "create_backup", "line": 110}
{"timestamp": "2025-07-21T22:46:52.353639", "level": "INFO", "logger": "cleanup_workflow", "message": "Created backup: backups\\economics_ai__cleanup_source3_20250721_184652.db", "module": "run_source_cleanup", "function": "execute_cleanup", "line": 133}
{"timestamp": "2025-07-21T22:46:52.356717", "level": "ERROR", "logger": "cleanup_workflow", "message": "Failed to process source 3: EOF when reading a line", "module": "run_source_cleanup", "function": "cleanup_multiple_sources", "line": 260}
{"timestamp": "2025-07-21T22:46:52.357762", "level": "ERROR", "logger": "cleanup_operations", "message": "Error during cleanup: EOF when reading a line", "module": "logging_config", "function": "log_error", "line": 89, "source_id": 3, "operation": "cleanup_error", "error_type": "EOFError", "exception": "Traceback (most recent call last):\n  File \"C:\\Users\\Robert Casanova\\OneDrive\\Documents\\economics-ai-dashboard-v2\\src\\pipeline\\run_source_cleanup.py\", line 253, in cleanup_multiple_sources\n    new_file = self.execute_cleanup(source_id, current_file, auto_confirm)\n  File \"C:\\Users\\Robert Casanova\\OneDrive\\Documents\\economics-ai-dashboard-v2\\src\\pipeline\\run_source_cleanup.py\", line 156, in execute_cleanup\n    response = input(\"\\nProceed with cleanup? (yes/no): \").lower().strip()\n               ~~~~~^^^^^^^^^^^^^^^^^^^^^^^^^^^^^^^^^^^^^^\nEOFError: EOF when reading a line"}
{"timestamp": "2025-07-21T22:47:58.083780", "level": "INFO", "logger": "root", "message": "Logging system initialized", "module": "logging_config", "function": "setup_logging", "line": 185}
{"timestamp": "2025-07-21T22:47:58.083934", "level": "INFO", "logger": "root", "message": "Log level: INFO", "module": "logging_config", "function": "setup_logging", "line": 186}
{"timestamp": "2025-07-21T22:47:58.084007", "level": "INFO", "logger": "root", "message": "Log directory: C:\\Users\\Robert Casanova\\OneDrive\\Documents\\economics-ai-dashboard-v2\\logs\\cleanup", "module": "logging_config", "function": "setup_logging", "line": 187}
{"timestamp": "2025-07-21T22:47:58.084090", "level": "INFO", "logger": "cleanup_workflow", "message": "Starting analysis for Source 3", "module": "run_source_cleanup", "function": "analyze_source", "line": 74}
{"timestamp": "2025-07-21T22:47:58.132517", "level": "INFO", "logger": "cleanup_workflow", "message": "Analysis complete for Source 3: 12 keep, 51 remove, 5 modify", "module": "run_source_cleanup", "function": "analyze_source", "line": 93}
{"timestamp": "2025-07-21T22:47:58.143666", "level": "INFO", "logger": "cleanup_operations", "message": "Cleanup action: analysis_complete - 68 records", "module": "logging_config", "function": "log_cleanup_action", "line": 66, "source_id": 3, "operation": "cleanup_analysis_complete", "records_affected": 68}
{"timestamp": "2025-07-21T22:47:58.144188", "level": "INFO", "logger": "cleanup_workflow", "message": "Starting cleanup execution for Source 3", "module": "run_source_cleanup", "function": "execute_cleanup", "line": 126}
{"timestamp": "2025-07-21T22:47:58.145927", "level": "INFO", "logger": "src.utils.backup_manager", "message": "Backup created: backups\\economics_ai__cleanup_source3_20250721_184758.db", "module": "backup_manager", "function": "create_backup", "line": 109}
{"timestamp": "2025-07-21T22:47:58.145982", "level": "INFO", "logger": "src.utils.backup_manager", "message": "Checksum: d41d8cd98f00b204e9800998ecf8427e", "module": "backup_manager", "function": "create_backup", "line": 110}
{"timestamp": "2025-07-21T22:47:58.146027", "level": "INFO", "logger": "cleanup_workflow", "message": "Created backup: backups\\economics_ai__cleanup_source3_20250721_184758.db", "module": "run_source_cleanup", "function": "execute_cleanup", "line": 133}
{"timestamp": "2025-07-21T22:47:58.149231", "level": "INFO", "logger": "cleanup_workflow", "message": "Executing cleanup operations...", "module": "run_source_cleanup", "function": "execute_cleanup", "line": 163}
{"timestamp": "2025-07-21T22:47:58.180658", "level": "INFO", "logger": "cleanup_operations", "message": "Starting cleanup for source 3", "module": "logging_config", "function": "log_cleanup_start", "line": 55, "source_id": 3, "operation": "cleanup_start", "records_affected": 12258}
{"timestamp": "2025-07-21T22:47:58.181957", "level": "INFO", "logger": "cleanup_workflow", "message": "Removed 51 records", "module": "run_source_cleanup", "function": "execute_cleanup", "line": 176}
{"timestamp": "2025-07-21T22:47:58.183443", "level": "INFO", "logger": "cleanup_workflow", "message": "Modified 5 records", "module": "run_source_cleanup", "function": "execute_cleanup", "line": 191}
{"timestamp": "2025-07-21T22:47:58.242601", "level": "INFO", "logger": "cleanup_workflow", "message": "Cleanup complete: 12258 -> 12207 records", "module": "run_source_cleanup", "function": "execute_cleanup", "line": 199}
{"timestamp": "2025-07-21T22:47:58.242661", "level": "INFO", "logger": "cleanup_workflow", "message": "Saved cleaned data to: ai_metrics_cleaned_source3.csv", "module": "run_source_cleanup", "function": "execute_cleanup", "line": 200}
{"timestamp": "2025-07-21T22:47:58.242724", "level": "INFO", "logger": "cleanup_operations", "message": "Cleanup completed for source 3", "module": "logging_config", "function": "log_cleanup_complete", "line": 78, "source_id": 3, "operation": "cleanup_complete"}
{"timestamp": "2025-07-21T23:34:02.107992", "level": "INFO", "logger": "root", "message": "Logging system initialized", "module": "logging_config", "function": "setup_logging", "line": 185}
{"timestamp": "2025-07-21T23:34:02.108123", "level": "INFO", "logger": "root", "message": "Log level: INFO", "module": "logging_config", "function": "setup_logging", "line": 186}
{"timestamp": "2025-07-21T23:34:02.108193", "level": "INFO", "logger": "root", "message": "Log directory: C:\\Users\\Robert Casanova\\OneDrive\\Documents\\economics-ai-dashboard-v2\\logs\\cleanup", "module": "logging_config", "function": "setup_logging", "line": 187}
{"timestamp": "2025-07-21T23:34:02.108261", "level": "INFO", "logger": "cleanup_workflow", "message": "Starting analysis for Source 4", "module": "run_source_cleanup", "function": "analyze_source", "line": 74}
{"timestamp": "2025-07-21T23:34:02.197311", "level": "INFO", "logger": "cleanup_workflow", "message": "Analysis complete for Source 4: 102 keep, 427 remove, 11 modify", "module": "run_source_cleanup", "function": "analyze_source", "line": 93}
{"timestamp": "2025-07-21T23:34:02.197426", "level": "INFO", "logger": "cleanup_operations", "message": "Cleanup action: analysis_complete - 540 records", "module": "logging_config", "function": "log_cleanup_action", "line": 66, "source_id": 4, "operation": "cleanup_analysis_complete", "records_affected": 540}
{"timestamp": "2025-07-21T23:34:02.198103", "level": "INFO", "logger": "cleanup_workflow", "message": "Starting analysis for Source 5", "module": "run_source_cleanup", "function": "analyze_source", "line": 74}
{"timestamp": "2025-07-21T23:34:02.244525", "level": "INFO", "logger": "cleanup_workflow", "message": "Analysis complete for Source 5: 28 keep, 92 remove, 6 modify", "module": "run_source_cleanup", "function": "analyze_source", "line": 93}
{"timestamp": "2025-07-21T23:34:02.244591", "level": "INFO", "logger": "cleanup_operations", "message": "Cleanup action: analysis_complete - 126 records", "module": "logging_config", "function": "log_cleanup_action", "line": 66, "source_id": 5, "operation": "cleanup_analysis_complete", "records_affected": 126}
{"timestamp": "2025-07-21T23:34:02.245122", "level": "INFO", "logger": "cleanup_workflow", "message": "Starting analysis for Source 6", "module": "run_source_cleanup", "function": "analyze_source", "line": 74}
{"timestamp": "2025-07-21T23:34:02.304028", "level": "INFO", "logger": "cleanup_workflow", "message": "Analysis complete for Source 6: 96 keep, 259 remove, 19 modify", "module": "run_source_cleanup", "function": "analyze_source", "line": 93}
{"timestamp": "2025-07-21T23:34:02.304097", "level": "INFO", "logger": "cleanup_operations", "message": "Cleanup action: analysis_complete - 374 records", "module": "logging_config", "function": "log_cleanup_action", "line": 66, "source_id": 6, "operation": "cleanup_analysis_complete", "records_affected": 374}
